<?xml version="1.0" ?>
<robot name="s2w" xmlns:xacro="https://www.ros.org/wiki/xacro">
    <!--linkki on pala robottia, voidaan määritellä matemaattisesti esim pallo, tai
    käyttää 3d mallinnettua palaa-->
    
    
    <!--                 LINK CHASSIS                  -->
    <link name="link_chassis">
        <pose>0 0 0.1 </pose> <!--xyz,roll,pich,yaw RPY-->
        <inertial>
            <mass value="5"/>
            <origin rpy="0 0 0" xyz="0 0 0.1"/>
            <inertia ixx="0.0395" ixy="0" ixz="0" iyy="0.1062" iyz="0" izz="0.1062"/>
        </inertial>
        
        <collision name="collision_chassis"> 
            <geometry>
                <box size="0.5 0.3 0.07"/>
            </geometry>
        </collision>
        
        <visual>
            <geometry>
                <box size="0.5 0.3 0.07"/>
            </geometry>
        </visual>
    </link>

    <!--                 LINK RIGHT WHEEL                  -->
    <link name="link_right_wheel">
        <inertial>
            <mass value="0.2"/>
            <origin rpy="0 1.5707 1.5707" xyz="0 0 0"/>
            <inertia ixx="0.0005266" ixy="0" ixz="0" iyy="0.0005266" iyz="0" izz="0.001"/>
        </inertial>
        
        <collision name="collision_right_wheel"> 
            <geometry>
                <cylinder lenght="0.04" radius="0.1"/>
            </geometry>
        </collision>
        
        <visual>
            <geometry>
                <cylinder length="0.04" radius="0.1"/>
            </geometry>
        </visual>
    </link>
    
    <joint name="joint_right_wheel" type="continuous">
        <origin rpy="0 1.5707 1.5707" xyz="-0.05 0.15 0"/>
        <child link="link_right_wheel"/>
        <parent link="link_chassis"/>
        <axis rpy="0 0 0" xyz="0 1 0"/>
        <limit effort="100" velocity="100"/>
        <joint_properties damping="1.0" friction="1.0"/>
    </joint>

    
    <!--                 LINK LEFT WHEEL                  --> 
    <link name="link_left_wheel">
        <inertial>
            <mass value="0.2"/>
            <origin rpy="0 1.5707 1.5707" xyz="0 0 0"/>
            <inertia ixx="0.0005266" ixy="0" ixz="0" iyy="0.0005266" iyz="0" izz="0.001"/>
        </inertial>
        
        <collision name="collision_left_wheel"> 
            <geometry>
                <cylinder lenght="0.04" radius="0.1"/>
            </geometry>
        </collision>
        
        <visual>
            <geometry>
                <cylinder length="0.04" radius="0.1"/>
            </geometry>
        </visual>
    </link>
    <joint name="joint_left_wheel" type="continuous">
        <origin rpy="0 1.5707 1.5707" xyz="-0.05 -0.15 0"/>
        <child link="link_left_wheel"/>
        <parent link="link_chassis"/>
        <axis rpy="0 0 0" xyz="0 1 0"/>
        <limit effort="100" velocity="100"/>
        <joint_properties damping="1.0" friction="1.0"/>
    </joint>

<!-- 
    <gazebo>
        <plugin filename="libgazebo_ross_diff_drive.so" name="differential_drive_controller">
        <legacyMode> false </legacyMode>
        <allwaysOn> true </allwaysOn>
        <updateRate> 20 </updateRate>
        <leftJoint> joint_left_wheel </leftJoint>
        <rightJoint> joint_right_wheel </rightJoint>
        <wheelSeparation> 0.2 </wheelSeparation>
        <wheelDiameter> 0.2 </wheelDiameter>
        <torguq> 0.1 </torguq>
        <commandTopic> cmd_vel </commandTopic>
        <odometryTopic> odom </odometryTopic>
        <odometryFrame> odom </odometryFrame>
        <robotBaseFrame> link_chassis </robotBaseFrame>
        </plugin>
    <gazebo/>
 -->

</robot>